2018-07-13 10:10:10,618 ERROR: Exception on /events/example_1.pdf [GET] [in /Users/jiahuiwu/anaconda/lib/python3.6/site-packages/flask/app.py:1761]
Traceback (most recent call last):
  File "/Users/jiahuiwu/anaconda/lib/python3.6/site-packages/flask/app.py", line 2292, in wsgi_app
    response = self.full_dispatch_request()
  File "/Users/jiahuiwu/anaconda/lib/python3.6/site-packages/flask/app.py", line 1815, in full_dispatch_request
    rv = self.handle_user_exception(e)
  File "/Users/jiahuiwu/anaconda/lib/python3.6/site-packages/flask/app.py", line 1718, in handle_user_exception
    reraise(exc_type, exc_value, tb)
  File "/Users/jiahuiwu/anaconda/lib/python3.6/site-packages/flask/_compat.py", line 35, in reraise
    raise value
  File "/Users/jiahuiwu/anaconda/lib/python3.6/site-packages/flask/app.py", line 1813, in full_dispatch_request
    rv = self.dispatch_request()
  File "/Users/jiahuiwu/anaconda/lib/python3.6/site-packages/flask/app.py", line 1799, in dispatch_request
    return self.view_functions[rule.endpoint](**req.view_args)
  File "/Users/jiahuiwu/Desktop/XCEL/app/routes.py", line 189, in event
    event = Event.query.filter_by(id=int(event)).first()
ValueError: invalid literal for int() with base 10: 'example_1.pdf'
2018-07-13 10:10:10,626 ERROR: Exception on /events/example_2.pdf [GET] [in /Users/jiahuiwu/anaconda/lib/python3.6/site-packages/flask/app.py:1761]
Traceback (most recent call last):
  File "/Users/jiahuiwu/anaconda/lib/python3.6/site-packages/flask/app.py", line 2292, in wsgi_app
    response = self.full_dispatch_request()
  File "/Users/jiahuiwu/anaconda/lib/python3.6/site-packages/flask/app.py", line 1815, in full_dispatch_request
    rv = self.handle_user_exception(e)
  File "/Users/jiahuiwu/anaconda/lib/python3.6/site-packages/flask/app.py", line 1718, in handle_user_exception
    reraise(exc_type, exc_value, tb)
  File "/Users/jiahuiwu/anaconda/lib/python3.6/site-packages/flask/_compat.py", line 35, in reraise
    raise value
  File "/Users/jiahuiwu/anaconda/lib/python3.6/site-packages/flask/app.py", line 1813, in full_dispatch_request
    rv = self.dispatch_request()
  File "/Users/jiahuiwu/anaconda/lib/python3.6/site-packages/flask/app.py", line 1799, in dispatch_request
    return self.view_functions[rule.endpoint](**req.view_args)
  File "/Users/jiahuiwu/Desktop/XCEL/app/routes.py", line 189, in event
    event = Event.query.filter_by(id=int(event)).first()
ValueError: invalid literal for int() with base 10: 'example_2.pdf'
2018-07-13 10:11:17,837 INFO: Microblog startup [in /Users/jiahuiwu/Desktop/XCEL/app/__init__.py:48]
2018-07-13 10:11:20,708 ERROR: Exception on /events/lion.jpg [GET] [in /Users/jiahuiwu/anaconda/lib/python3.6/site-packages/flask/app.py:1761]
Traceback (most recent call last):
  File "/Users/jiahuiwu/anaconda/lib/python3.6/site-packages/flask/app.py", line 2292, in wsgi_app
    response = self.full_dispatch_request()
  File "/Users/jiahuiwu/anaconda/lib/python3.6/site-packages/flask/app.py", line 1815, in full_dispatch_request
    rv = self.handle_user_exception(e)
  File "/Users/jiahuiwu/anaconda/lib/python3.6/site-packages/flask/app.py", line 1718, in handle_user_exception
    reraise(exc_type, exc_value, tb)
  File "/Users/jiahuiwu/anaconda/lib/python3.6/site-packages/flask/_compat.py", line 35, in reraise
    raise value
  File "/Users/jiahuiwu/anaconda/lib/python3.6/site-packages/flask/app.py", line 1813, in full_dispatch_request
    rv = self.dispatch_request()
  File "/Users/jiahuiwu/anaconda/lib/python3.6/site-packages/flask/app.py", line 1799, in dispatch_request
    return self.view_functions[rule.endpoint](**req.view_args)
  File "/Users/jiahuiwu/Desktop/XCEL/app/routes.py", line 189, in event
    event = Event.query.filter_by(id=int(event)).first()
ValueError: invalid literal for int() with base 10: 'lion.jpg'
2018-07-13 10:12:06,058 INFO: Microblog startup [in /Users/jiahuiwu/Desktop/XCEL/app/__init__.py:48]
2018-07-13 10:12:09,875 ERROR: Exception on /events/lion.jpg [GET] [in /Users/jiahuiwu/anaconda/lib/python3.6/site-packages/flask/app.py:1761]
Traceback (most recent call last):
  File "/Users/jiahuiwu/anaconda/lib/python3.6/site-packages/flask/app.py", line 2292, in wsgi_app
    response = self.full_dispatch_request()
  File "/Users/jiahuiwu/anaconda/lib/python3.6/site-packages/flask/app.py", line 1815, in full_dispatch_request
    rv = self.handle_user_exception(e)
  File "/Users/jiahuiwu/anaconda/lib/python3.6/site-packages/flask/app.py", line 1718, in handle_user_exception
    reraise(exc_type, exc_value, tb)
  File "/Users/jiahuiwu/anaconda/lib/python3.6/site-packages/flask/_compat.py", line 35, in reraise
    raise value
  File "/Users/jiahuiwu/anaconda/lib/python3.6/site-packages/flask/app.py", line 1813, in full_dispatch_request
    rv = self.dispatch_request()
  File "/Users/jiahuiwu/anaconda/lib/python3.6/site-packages/flask/app.py", line 1799, in dispatch_request
    return self.view_functions[rule.endpoint](**req.view_args)
  File "/Users/jiahuiwu/Desktop/XCEL/app/routes.py", line 189, in event
    event = Event.query.filter_by(id=int(event)).first()
ValueError: invalid literal for int() with base 10: 'lion.jpg'
2018-07-13 10:12:35,414 INFO: Microblog startup [in /Users/jiahuiwu/Desktop/XCEL/app/__init__.py:48]
2018-07-13 10:12:40,928 ERROR: Exception on /events/lion.jpg [GET] [in /Users/jiahuiwu/anaconda/lib/python3.6/site-packages/flask/app.py:1761]
Traceback (most recent call last):
  File "/Users/jiahuiwu/anaconda/lib/python3.6/site-packages/flask/app.py", line 2292, in wsgi_app
    response = self.full_dispatch_request()
  File "/Users/jiahuiwu/anaconda/lib/python3.6/site-packages/flask/app.py", line 1815, in full_dispatch_request
    rv = self.handle_user_exception(e)
  File "/Users/jiahuiwu/anaconda/lib/python3.6/site-packages/flask/app.py", line 1718, in handle_user_exception
    reraise(exc_type, exc_value, tb)
  File "/Users/jiahuiwu/anaconda/lib/python3.6/site-packages/flask/_compat.py", line 35, in reraise
    raise value
  File "/Users/jiahuiwu/anaconda/lib/python3.6/site-packages/flask/app.py", line 1813, in full_dispatch_request
    rv = self.dispatch_request()
  File "/Users/jiahuiwu/anaconda/lib/python3.6/site-packages/flask/app.py", line 1799, in dispatch_request
    return self.view_functions[rule.endpoint](**req.view_args)
  File "/Users/jiahuiwu/Desktop/XCEL/app/routes.py", line 189, in event
    event = Event.query.filter_by(id=int(event)).first()
ValueError: invalid literal for int() with base 10: 'lion.jpg'
2018-07-13 10:13:22,291 INFO: Microblog startup [in /Users/jiahuiwu/Desktop/XCEL/app/__init__.py:48]
2018-07-13 10:13:28,610 INFO: Microblog startup [in /Users/jiahuiwu/Desktop/XCEL/app/__init__.py:48]
2018-07-13 10:15:25,368 INFO: Microblog startup [in /Users/jiahuiwu/Desktop/XCEL/app/__init__.py:48]
2018-07-13 10:15:29,707 ERROR: Exception on /events/1 [GET] [in /Users/jiahuiwu/anaconda/lib/python3.6/site-packages/flask/app.py:1761]
Traceback (most recent call last):
  File "/Users/jiahuiwu/anaconda/lib/python3.6/site-packages/flask/app.py", line 2292, in wsgi_app
    response = self.full_dispatch_request()
  File "/Users/jiahuiwu/anaconda/lib/python3.6/site-packages/flask/app.py", line 1815, in full_dispatch_request
    rv = self.handle_user_exception(e)
  File "/Users/jiahuiwu/anaconda/lib/python3.6/site-packages/flask/app.py", line 1718, in handle_user_exception
    reraise(exc_type, exc_value, tb)
  File "/Users/jiahuiwu/anaconda/lib/python3.6/site-packages/flask/_compat.py", line 35, in reraise
    raise value
  File "/Users/jiahuiwu/anaconda/lib/python3.6/site-packages/flask/app.py", line 1813, in full_dispatch_request
    rv = self.dispatch_request()
  File "/Users/jiahuiwu/anaconda/lib/python3.6/site-packages/flask/app.py", line 1799, in dispatch_request
    return self.view_functions[rule.endpoint](**req.view_args)
  File "/Users/jiahuiwu/Desktop/XCEL/app/routes.py", line 191, in event
    images = event.related_images().items
AttributeError: 'BaseQuery' object has no attribute 'items'
2018-07-22 20:26:47,735 INFO: Microblog startup [in /Users/jiahuiwu/Desktop/XCEL/app/__init__.py:48]
2018-07-30 14:21:40,573 INFO: Microblog startup [in /Users/jiahuiwu/Desktop/XCEL/app/__init__.py:48]
2018-07-30 14:21:50,675 ERROR: Exception on / [GET] [in /Users/jiahuiwu/anaconda/lib/python3.6/site-packages/flask/app.py:1761]
Traceback (most recent call last):
  File "/Users/jiahuiwu/anaconda/lib/python3.6/site-packages/flask/app.py", line 2292, in wsgi_app
    response = self.full_dispatch_request()
  File "/Users/jiahuiwu/anaconda/lib/python3.6/site-packages/flask/app.py", line 1815, in full_dispatch_request
    rv = self.handle_user_exception(e)
  File "/Users/jiahuiwu/anaconda/lib/python3.6/site-packages/flask/app.py", line 1718, in handle_user_exception
    reraise(exc_type, exc_value, tb)
  File "/Users/jiahuiwu/anaconda/lib/python3.6/site-packages/flask/_compat.py", line 35, in reraise
    raise value
  File "/Users/jiahuiwu/anaconda/lib/python3.6/site-packages/flask/app.py", line 1813, in full_dispatch_request
    rv = self.dispatch_request()
  File "/Users/jiahuiwu/anaconda/lib/python3.6/site-packages/flask/app.py", line 1799, in dispatch_request
    return self.view_functions[rule.endpoint](**req.view_args)
  File "/Users/jiahuiwu/Desktop/XCEL/app/routes.py", line 28, in index
    return render_template("index.html", title="Home page", slide=slideshow[0], slides=slideshow[1:], len=len(slideshow))
IndexError: list index out of range
