2018-07-30 14:22:15,924 ERROR: Exception on / [GET] [in /Users/jiahuiwu/anaconda/lib/python3.6/site-packages/flask/app.py:1761]
Traceback (most recent call last):
  File "/Users/jiahuiwu/anaconda/lib/python3.6/site-packages/flask/app.py", line 2292, in wsgi_app
    response = self.full_dispatch_request()
  File "/Users/jiahuiwu/anaconda/lib/python3.6/site-packages/flask/app.py", line 1815, in full_dispatch_request
    rv = self.handle_user_exception(e)
  File "/Users/jiahuiwu/anaconda/lib/python3.6/site-packages/flask/app.py", line 1718, in handle_user_exception
    reraise(exc_type, exc_value, tb)
  File "/Users/jiahuiwu/anaconda/lib/python3.6/site-packages/flask/_compat.py", line 35, in reraise
    raise value
  File "/Users/jiahuiwu/anaconda/lib/python3.6/site-packages/flask/app.py", line 1813, in full_dispatch_request
    rv = self.dispatch_request()
  File "/Users/jiahuiwu/anaconda/lib/python3.6/site-packages/flask/app.py", line 1799, in dispatch_request
    return self.view_functions[rule.endpoint](**req.view_args)
  File "/Users/jiahuiwu/Desktop/XCEL/app/routes.py", line 28, in index
    return render_template("index.html", title="Home page", slide=slideshow[0], slides=slideshow[1:], len=len(slideshow))
IndexError: list index out of range
2018-07-30 14:22:19,560 ERROR: Exception on / [GET] [in /Users/jiahuiwu/anaconda/lib/python3.6/site-packages/flask/app.py:1761]
Traceback (most recent call last):
  File "/Users/jiahuiwu/anaconda/lib/python3.6/site-packages/flask/app.py", line 2292, in wsgi_app
    response = self.full_dispatch_request()
  File "/Users/jiahuiwu/anaconda/lib/python3.6/site-packages/flask/app.py", line 1815, in full_dispatch_request
    rv = self.handle_user_exception(e)
  File "/Users/jiahuiwu/anaconda/lib/python3.6/site-packages/flask/app.py", line 1718, in handle_user_exception
    reraise(exc_type, exc_value, tb)
  File "/Users/jiahuiwu/anaconda/lib/python3.6/site-packages/flask/_compat.py", line 35, in reraise
    raise value
  File "/Users/jiahuiwu/anaconda/lib/python3.6/site-packages/flask/app.py", line 1813, in full_dispatch_request
    rv = self.dispatch_request()
  File "/Users/jiahuiwu/anaconda/lib/python3.6/site-packages/flask/app.py", line 1799, in dispatch_request
    return self.view_functions[rule.endpoint](**req.view_args)
  File "/Users/jiahuiwu/Desktop/XCEL/app/routes.py", line 28, in index
    return render_template("index.html", title="Home page", slide=slideshow[0], slides=slideshow[1:], len=len(slideshow))
IndexError: list index out of range
2018-07-30 14:22:27,002 INFO: Microblog startup [in /Users/jiahuiwu/Desktop/XCEL/app/__init__.py:48]
2018-07-30 14:22:28,731 ERROR: Exception on / [GET] [in /Users/jiahuiwu/anaconda/lib/python3.6/site-packages/flask/app.py:1761]
Traceback (most recent call last):
  File "/Users/jiahuiwu/anaconda/lib/python3.6/site-packages/flask/app.py", line 2292, in wsgi_app
    response = self.full_dispatch_request()
  File "/Users/jiahuiwu/anaconda/lib/python3.6/site-packages/flask/app.py", line 1816, in full_dispatch_request
    return self.finalize_request(rv)
  File "/Users/jiahuiwu/anaconda/lib/python3.6/site-packages/flask/app.py", line 1831, in finalize_request
    response = self.make_response(rv)
  File "/Users/jiahuiwu/anaconda/lib/python3.6/site-packages/flask/app.py", line 1957, in make_response
    'The view function did not return a valid response. The'
TypeError: The view function did not return a valid response. The function either returned None or ended without a return statement.
2018-07-30 14:23:07,183 INFO: Microblog startup [in /Users/jiahuiwu/Desktop/XCEL/app/__init__.py:48]
2018-07-30 14:23:08,921 ERROR: Exception on / [GET] [in /Users/jiahuiwu/anaconda/lib/python3.6/site-packages/flask/app.py:1761]
Traceback (most recent call last):
  File "/Users/jiahuiwu/anaconda/lib/python3.6/site-packages/flask/app.py", line 2292, in wsgi_app
    response = self.full_dispatch_request()
  File "/Users/jiahuiwu/anaconda/lib/python3.6/site-packages/flask/app.py", line 1815, in full_dispatch_request
    rv = self.handle_user_exception(e)
  File "/Users/jiahuiwu/anaconda/lib/python3.6/site-packages/flask/app.py", line 1718, in handle_user_exception
    reraise(exc_type, exc_value, tb)
  File "/Users/jiahuiwu/anaconda/lib/python3.6/site-packages/flask/_compat.py", line 35, in reraise
    raise value
  File "/Users/jiahuiwu/anaconda/lib/python3.6/site-packages/flask/app.py", line 1813, in full_dispatch_request
    rv = self.dispatch_request()
  File "/Users/jiahuiwu/anaconda/lib/python3.6/site-packages/flask/app.py", line 1799, in dispatch_request
    return self.view_functions[rule.endpoint](**req.view_args)
  File "/Users/jiahuiwu/Desktop/XCEL/app/routes.py", line 28, in index
    return render_template("index.html", title="Home page", slide=slideshow[0], slides=slideshow[1:], len=len(slideshow))
IndexError: list index out of range
2018-07-30 14:23:10,925 ERROR: Exception on / [GET] [in /Users/jiahuiwu/anaconda/lib/python3.6/site-packages/flask/app.py:1761]
Traceback (most recent call last):
  File "/Users/jiahuiwu/anaconda/lib/python3.6/site-packages/flask/app.py", line 2292, in wsgi_app
    response = self.full_dispatch_request()
  File "/Users/jiahuiwu/anaconda/lib/python3.6/site-packages/flask/app.py", line 1815, in full_dispatch_request
    rv = self.handle_user_exception(e)
  File "/Users/jiahuiwu/anaconda/lib/python3.6/site-packages/flask/app.py", line 1718, in handle_user_exception
    reraise(exc_type, exc_value, tb)
  File "/Users/jiahuiwu/anaconda/lib/python3.6/site-packages/flask/_compat.py", line 35, in reraise
    raise value
  File "/Users/jiahuiwu/anaconda/lib/python3.6/site-packages/flask/app.py", line 1813, in full_dispatch_request
    rv = self.dispatch_request()
  File "/Users/jiahuiwu/anaconda/lib/python3.6/site-packages/flask/app.py", line 1799, in dispatch_request
    return self.view_functions[rule.endpoint](**req.view_args)
  File "/Users/jiahuiwu/Desktop/XCEL/app/routes.py", line 28, in index
    return render_template("index.html", title="Home page", slide=slideshow[0], slides=slideshow[1:], len=len(slideshow))
IndexError: list index out of range
2018-09-24 16:01:58,952 INFO: Microblog startup [in /Users/jiahuiwu/Desktop/XCEL/app/__init__.py:48]
2018-09-24 16:34:32,672 ERROR: Exception on /register_league/2 [GET] [in /Users/jiahuiwu/anaconda/lib/python3.6/site-packages/flask/app.py:1761]
Traceback (most recent call last):
  File "/Users/jiahuiwu/anaconda/lib/python3.6/site-packages/flask/app.py", line 2292, in wsgi_app
    response = self.full_dispatch_request()
  File "/Users/jiahuiwu/anaconda/lib/python3.6/site-packages/flask/app.py", line 1815, in full_dispatch_request
    rv = self.handle_user_exception(e)
  File "/Users/jiahuiwu/anaconda/lib/python3.6/site-packages/flask/app.py", line 1718, in handle_user_exception
    reraise(exc_type, exc_value, tb)
  File "/Users/jiahuiwu/anaconda/lib/python3.6/site-packages/flask/_compat.py", line 35, in reraise
    raise value
  File "/Users/jiahuiwu/anaconda/lib/python3.6/site-packages/flask/app.py", line 1813, in full_dispatch_request
    rv = self.dispatch_request()
  File "/Users/jiahuiwu/anaconda/lib/python3.6/site-packages/flask/app.py", line 1799, in dispatch_request
    return self.view_functions[rule.endpoint](**req.view_args)
  File "/Users/jiahuiwu/Desktop/XCEL/app/routes.py", line 307, in register_league
    league = League.query.filter_by(id=int(league)).first()
  File "/Users/jiahuiwu/anaconda/lib/python3.6/site-packages/werkzeug/local.py", line 347, in __getattr__
    return getattr(self._get_current_object(), name)
AttributeError: 'AnonymousUserMixin' object has no attribute 'get_teams'
2018-09-24 16:35:02,157 ERROR: Exception on /register_league/1 [GET] [in /Users/jiahuiwu/anaconda/lib/python3.6/site-packages/flask/app.py:1761]
Traceback (most recent call last):
  File "/Users/jiahuiwu/anaconda/lib/python3.6/site-packages/flask/app.py", line 2292, in wsgi_app
    response = self.full_dispatch_request()
  File "/Users/jiahuiwu/anaconda/lib/python3.6/site-packages/flask/app.py", line 1815, in full_dispatch_request
    rv = self.handle_user_exception(e)
  File "/Users/jiahuiwu/anaconda/lib/python3.6/site-packages/flask/app.py", line 1718, in handle_user_exception
    reraise(exc_type, exc_value, tb)
  File "/Users/jiahuiwu/anaconda/lib/python3.6/site-packages/flask/_compat.py", line 35, in reraise
    raise value
  File "/Users/jiahuiwu/anaconda/lib/python3.6/site-packages/flask/app.py", line 1813, in full_dispatch_request
    rv = self.dispatch_request()
  File "/Users/jiahuiwu/anaconda/lib/python3.6/site-packages/flask/app.py", line 1799, in dispatch_request
    return self.view_functions[rule.endpoint](**req.view_args)
  File "/Users/jiahuiwu/Desktop/XCEL/app/routes.py", line 307, in register_league
    league = League.query.filter_by(id=int(league)).first()
  File "/Users/jiahuiwu/anaconda/lib/python3.6/site-packages/werkzeug/local.py", line 347, in __getattr__
    return getattr(self._get_current_object(), name)
AttributeError: 'AnonymousUserMixin' object has no attribute 'get_teams'
